Workbook
Name 송보근: #REF!

Sheet Usage Apr 2026
A1: Please don't change this sheet and data except the column 'Verified' with the color light gold. If necessary, contact Yunseul Lee via Slack 1:1 DM. | J1: ㅇ
A2: You verify the cost of the last month and leave the mark V in the column 'Verified'. If the value in the last month is wrong, give the description to Yunseul Lee
A3: Provider | B3: Entity | C3: Studio | D3: Team | E3: Project | F3: Team code | G3: Project code | H3: Teams Room Pro | I3: Owner | J3: Cost Reviewer | K3: verified | L3: May 2025(KRW) | M3: June 2025(KRW) | N3: July 2025(KRW) | O3: Aug 2025(KRW) | P3: Sep 2025(KRW) | Q3: Oct 2025(KRW) | R3: Nov 2025(KRW) | S3: Dec 2025(KRW) | T3: Jan 2026(KRW) | U3: Feb 2026(KRW) | V3: Mar 2026(KRW) | W3: Apr 2027(KRW) | X3: Apr 2026 (USD or KRW) | Y3: Diff (KRW) (this month - last month) | Z3: Diff rate | AA3: Entity Code
A4: =VLOOKUP($H4,Akamai!$A:$H,2,0) -> Akamai | B4: =VLOOKUP($H4,Akamai!$A:$H,3,0) -> KRAFTON HQ | C4: =VLOOKUP($H4,Akamai!$A:$H,4,0) -> KRAFTON HQ | D4: =VLOOKUP($H4,Akamai!$A:$H,5,0) -> Publishing Tech PM Part | E4: =VLOOKUP($H4,Akamai!$A:$H,6,0) -> Dark and Darker_Mobile | F4: =VLOOKUP(표9[[#This Row],[Team]],표1[[내역]:[코스트 센터]],2,0) -> 101269 | G4: =VLOOKUP(표9[[#This Row],[Project]],표2[],2,0) -> P100030073 | H4: Dark&DarkerMoblie | I4: =VLOOKUP($H4,Akamai!$A:$H,7,0) -> 김정언 | J4: =VLOOKUP($H4,Akamai!$A:$H,8,0) -> 김정언 | K4: v | L4: 191794 | M4: 12151797 | N4: 1647138 | O4: 998557 | P4: 687485 | Q4: 656031 | R4: 372478 | S4: 371022 | T4: 241926 | U4: 56897 | V4: 49010 | W4: =ROUND(표9[[#This Row],[Apr 2026 (USD or KRW)]],0) -> 0 | Y4: =표9[[#This Row],[Apr 2027(KRW)]]-표9[[#This Row],[Mar 2026(KRW)]] -> -49010 | Z4: =IF(V4=0,"",(W4-V4)/V4) -> -1 | AA4: =VLOOKUP(표9[[#This Row],[Team]],표1[],3,0) -> 1000
A5: =VLOOKUP($H5,Akamai!$A:$H,2,0) -> Akamai | B5: =VLOOKUP($H5,Akamai!$A:$H,3,0) -> KRAFTON HQ | C5: =VLOOKUP($H5,Akamai!$A:$H,4,0) -> KRAFTON HQ | D5: =VLOOKUP($H5,Akamai!$A:$H,5,0) -> IT Dept. | E5: =VLOOKUP($H5,Akamai!$A:$H,6,0) -> OVERHEAD/OTHERS | F5: =VLOOKUP(표9[[#This Row],[Team]],표1[[내역]:[코스트 센터]],2,0) -> 100036 | G5: =VLOOKUP(표9[[#This Row],[Project]],표2[],2,0) -> I100099999 | H5: Global Traffic Management | I5: =VLOOKUP($H5,Akamai!$A:$H,7,0) -> 이윤슬 | J5: =VLOOKUP($H5,Akamai!$A:$H,8,0) -> 이윤슬 | K5: v | L5: 2850000 | M5: 2850000 | N5: 2850000 | O5: 2850000 | P5: 2850000 | Q5: 2850000 | R5: 2850000 | S5: 2850000 | T5: 2850000 | U5: 2850000 | V5: 2935500 | W5: =ROUND(표9[[#This Row],[Apr 2026 (USD or KRW)]],0) -> 0 | Y5: =표9[[#This Row],[Apr 2027(KRW)]]-표9[[#This Row],[Mar 2026(KRW)]] -> -2935500 | Z5: =IF(V5=0,"",(W5-V5)/V5) -> -1 | AA5: =VLOOKUP(표9[[#This Row],[Team]],표1[],3,0) -> 1000
A6: =VLOOKUP($H6,Akamai!$A:$H,2,0) -> Akamai | B6: =VLOOKUP($H6,Akamai!$A:$H,3,0) -> KRAFTON HQ | C6: =VLOOKUP($H6,Akamai!$A:$H,4,0) -> KRAFTON HQ | D6: =VLOOKUP($H6,Akamai!$A:$H,5,0) -> KOS Engineering Dept. | E6: =VLOOKUP($H6,Akamai!$A:$H,6,0) -> GPP | F6: =VLOOKUP(표9[[#This Row],[Team]],표1[[내역]:[코스트 센터]],2,0) -> 100025 | G6: =VLOOKUP(표9[[#This Row],[Project]],표2[],2,0) -> I100090813 | H6: GPP Dept | I6: =VLOOKUP($H6,Akamai!$A:$H,7,0) -> 이의석 | J6: =VLOOKUP($H6,Akamai!$A:$H,8,0) -> 이의석 | K6: v | L6: 16500000 | M6: 16500000 | N6: 17302333 | O6: 16500000 | P6: 16500000 | Q6: 16500000 | R6: 16500000 | S6: 19189620 | T6: 16500000 | U6: 16500000 | V6: 16995000 | W6: =ROUND(표9[[#This Row],[Apr 2026 (USD or KRW)]],0) -> 0 | Y6: =표9[[#This Row],[Apr 2027(KRW)]]-표9[[#This Row],[Mar 2026(KRW)]] -> -16995000 | Z6: =IF(V6=0,"",(W6-V6)/V6) -> -1 | AA6: =VLOOKUP(표9[[#This Row],[Team]],표1[],3,0) -> 1000
A7: =VLOOKUP($H7,Akamai!$A:$H,2,0) -> Akamai | B7: =VLOOKUP($H7,Akamai!$A:$H,3,0) -> KRAFTON HQ | C7: =VLOOKUP($H7,Akamai!$A:$H,4,0) -> KRAFTON HQ | D7: =VLOOKUP($H7,Akamai!$A:$H,5,0) -> IT Dept. | E7: =VLOOKUP($H7,Akamai!$A:$H,6,0) -> OVERHEAD/OTHERS | F7: =VLOOKUP(표9[[#This Row],[Team]],표1[[내역]:[코스트 센터]],2,0) -> 100036 | G7: =VLOOKUP(표9[[#This Row],[Project]],표2[],2,0) -> I100099999 | H7: IT Dept | I7: =VLOOKUP($H7,Akamai!$A:$H,7,0) -> 백용원 | J7: =VLOOKUP($H7,Akamai!$A:$H,8,0) -> 백용원 | K7: v | L7: 6736 | M7: 6295 | N7: 18686 | O7: 0 | P7: 0 | Q7: 0 | R7: 0 | S7: 22440 | T7: 0 | U7: 0 | V7: 0 | W7: =ROUND(표9[[#This Row],[Apr 2026 (USD or KRW)]],0) -> 0 | Y7: =표9[[#This Row],[Apr 2027(KRW)]]-표9[[#This Row],[Mar 2026(KRW)]] -> 0 | Z7: =IF(V7=0,"",(W7-V7)/V7) | AA7: =VLOOKUP(표9[[#This Row],[Team]],표1[],3,0) -> 1000
A8: =VLOOKUP($H8,Akamai!$A:$H,2,0) -> Akamai | B8: =VLOOKUP($H8,Akamai!$A:$H,3,0) -> KRAFTON HQ | C8: =VLOOKUP($H8,Akamai!$A:$H,4,0) -> PUBG NewState | D8: =VLOOKUP($H8,Akamai!$A:$H,5,0) -> [N/A]New State Dev Div. | E8: =VLOOKUP($H8,Akamai!$A:$H,6,0) -> PUBG:NEW STATE | F8: =VLOOKUP(표9[[#This Row],[Team]],표1[[내역]:[코스트 센터]],2,0) -> 100368 | G8: =VLOOKUP(표9[[#This Row],[Project]],표2[],2,0) -> P100030014 | H8: NewStateMobile | I8: 김태완 | J8: =VLOOKUP($H8,Akamai!$A:$H,8,0) -> 김태완 | K8: v | L8: 6202222 | M8: 6160035 | N8: 6218633 | O8: 6584628 | P8: 5198312 | Q8: 6649060 | R8: 6806509 | S8: 5804815 | T8: 6546446 | U8: 5466648 | V8: 5759285 | W8: =ROUND(표9[[#This Row],[Apr 2026 (USD or KRW)]],0) -> 0 | Y8: =표9[[#This Row],[Apr 2027(KRW)]]-표9[[#This Row],[Mar 2026(KRW)]] -> -5759285 | Z8: =IF(V8=0,"",(W8-V8)/V8) -> -1 | AA8: =VLOOKUP(표9[[#This Row],[Team]],표1[],3,0) -> 1000
A9: =VLOOKUP($H9,Akamai!$A:$H,2,0) -> Akamai | B9: =VLOOKUP($H9,Akamai!$A:$H,3,0) -> KRAFTON HQ | C9: =VLOOKUP($H9,Akamai!$A:$H,4,0) -> KRAFTON HQ | D9: =VLOOKUP($H9,Akamai!$A:$H,5,0) -> Publishing Tech PM Part | E9: =VLOOKUP($H9,Akamai!$A:$H,6,0) -> OVERHEAD/OTHERS | F9: =VLOOKUP(표9[[#This Row],[Team]],표1[[내역]:[코스트 센터]],2,0) -> 101269 | G9: =VLOOKUP(표9[[#This Row],[Project]],표2[],2,0) -> I100099999 | H9: NitroSmash | I9: =VLOOKUP($H9,Akamai!$A:$H,7,0) -> 김정언 | J9: =VLOOKUP($H9,Akamai!$A:$H,8,0) -> 김정언 | K9: v | P9: 160 | Q9: 1 | R9: 1 | S9: 1 | T9: 2 | U9: 0 | V9: 0 | W9: =ROUND(표9[[#This Row],[Apr 2026 (USD or KRW)]],0) -> 0 | Y9: =표9[[#This Row],[Apr 2027(KRW)]]-표9[[#This Row],[Mar 2026(KRW)]] -> 0 | Z9: =IF(V9=0,"",(W9-V9)/V9) | AA9: =VLOOKUP(표9[[#This Row],[Team]],표1[],3,0) -> 1000
A10: =VLOOKUP($H10,Akamai!$A:$H,2,0) -> Akamai | B10: =VLOOKUP($H10,Akamai!$A:$H,3,0) -> KRAFTON HQ | C10: =VLOOKUP($H10,Akamai!$A:$H,4,0) -> KRAFTON HQ | D10: =VLOOKUP($H10,Akamai!$A:$H,5,0) -> IT Dept. | E10: =VLOOKUP($H10,Akamai!$A:$H,6,0) -> OVERHEAD/OTHERS | F10: =VLOOKUP(표9[[#This Row],[Team]],표1[[내역]:[코스트 센터]],2,0) -> 100036 | G10: =VLOOKUP(표9[[#This Row],[Project]],표2[],2,0) -> I100099999 | H10: Protect&Perform SOA with Premium | I10: =VLOOKUP($H10,Akamai!$A:$H,7,0) -> 이윤슬 | J10: =VLOOKUP($H10,Akamai!$A:$H,8,0) -> 이윤슬 | K10: v | L10: 22950000 | M10: 22950000 | N10: 22950000 | O10: 22950000 | P10: 22950000 | Q10: 22950000 | R10: 22950000 | S10: 22950000 | T10: 22950000 | U10: 22950000 | V10: 23638500 | W10: =ROUND(표9[[#This Row],[Apr 2026 (USD or KRW)]],0) -> 0 | Y10: =표9[[#This Row],[Apr 2027(KRW)]]-표9[[#This Row],[Mar 2026(KRW)]] -> -23638500 | Z10: =IF(V10=0,"",(W10-V10)/V10) -> -1 | AA10: =VLOOKUP(표9[[#This Row],[Team]],표1[],3,0) -> 1000
A11: =VLOOKUP($H11,Akamai!$A:$H,2,0) -> Akamai | B11: =VLOOKUP($H11,Akamai!$A:$H,3,0) -> KRAFTON HQ | C11: =VLOOKUP($H11,Akamai!$A:$H,4,0) -> KRAFTON HQ | D11: =VLOOKUP($H11,Akamai!$A:$H,5,0) -> BGMI DevOps Team | E11: =VLOOKUP($H11,Akamai!$A:$H,6,0) -> (2022)BATTLEGROUNDS_MOBILE_IN | F11: =VLOOKUP(표9[[#This Row],[Team]],표1[[내역]:[코스트 센터]],2,0) -> 100553 | G11: =VLOOKUP(표9[[#This Row],[Project]],표2[],2,0) -> P100130012 | H11: PUBG India | I11: =VLOOKUP($H11,Akamai!$A:$H,7,0) -> 이돈현 | J11: =VLOOKUP($H11,Akamai!$A:$H,8,0) -> 이돈현 | K11: v | L11: 717155429 | M11: 534113519 | N11: 921689465 | O11: 689008671 | P11: 899905653 | Q11: 599777963 | R11: 865196956 | S11: 616285601 | T11: 844093018 | U11: 380658986 | V11: 468732101 | W11: =ROUND(표9[[#This Row],[Apr 2026 (USD or KRW)]],0) -> 0 | Y11: =표9[[#This Row],[Apr 2027(KRW)]]-표9[[#This Row],[Mar 2026(KRW)]] -> -468732101 | Z11: =IF(V11=0,"",(W11-V11)/V11) -> -1 | AA11: =VLOOKUP(표9[[#This Row],[Team]],표1[],3,0) -> 1000
A12: =VLOOKUP($H12,Akamai!$A:$H,2,0) -> Akamai | B12: =VLOOKUP($H12,Akamai!$A:$H,3,0) -> KRAFTON HQ | C12: =VLOOKUP($H12,Akamai!$A:$H,4,0) -> KRAFTON HQ | D12: =VLOOKUP($H12,Akamai!$A:$H,5,0) -> PUBG PC&Console Dev Div. | E12: =VLOOKUP($H12,Akamai!$A:$H,6,0) -> BATTLEGROUNDS_PC/CONSOLE | F12: =VLOOKUP(표9[[#This Row],[Team]],표1[[내역]:[코스트 센터]],2,0) -> 100414 | G12: =VLOOKUP(표9[[#This Row],[Project]],표2[],2,0) -> P100010012 | H12: PUBG PC/Console | I12: =VLOOKUP($H12,Akamai!$A:$H,7,0) -> 김정헌 | J12: =VLOOKUP($H12,Akamai!$A:$H,8,0) -> 최준석 | K12: v | L12: 1485849 | M12: 1439358 | N12: 1637229 | O12: 1394062 | P12: 1300651 | Q12: 1293148 | R12: 1354057 | S12: 1437475 | T12: 1357700 | U12: 1187780 | V12: 1542493 | W12: =ROUND(표9[[#This Row],[Apr 2026 (USD or KRW)]],0) -> 0 | Y12: =표9[[#This Row],[Apr 2027(KRW)]]-표9[[#This Row],[Mar 2026(KRW)]] -> -1542493 | Z12: =IF(V12=0,"",(W12-V12)/V12) -> -1 | AA12: =VLOOKUP(표9[[#This Row],[Team]],표1[],3,0) -> 1000
A13: =VLOOKUP($H13,Akamai!$A:$H,2,0) -> Akamai | B13: =VLOOKUP($H13,Akamai!$A:$H,3,0) -> KRAFTON HQ | C13: =VLOOKUP($H13,Akamai!$A:$H,4,0) -> KRAFTON HQ | D13: =VLOOKUP($H13,Akamai!$A:$H,5,0) -> IT Dept. | E13: =VLOOKUP($H13,Akamai!$A:$H,6,0) -> OVERHEAD/OTHERS | F13: =VLOOKUP(표9[[#This Row],[Team]],표1[[내역]:[코스트 센터]],2,0) -> 100036 | G13: =VLOOKUP(표9[[#This Row],[Project]],표2[],2,0) -> I100099999 | H13: SSL Network Access-Third-party - VIP | I13: =VLOOKUP($H13,Akamai!$A:$H,7,0) -> 이윤슬 | J13: =VLOOKUP($H13,Akamai!$A:$H,8,0) -> 이윤슬 | K13: v | L13: 250000 | M13: 250000 | N13: 250000 | O13: 250000 | P13: 250000 | Q13: 250000 | R13: 250000 | S13: 250000 | T13: 250000 | U13: 250000 | V13: 257500 | W13: =ROUND(표9[[#This Row],[Apr 2026 (USD or KRW)]],0) -> 0 | Y13: =표9[[#This Row],[Apr 2027(KRW)]]-표9[[#This Row],[Mar 2026(KRW)]] -> -257500 | Z13: =IF(V13=0,"",(W13-V13)/V13) -> -1 | AA13: =VLOOKUP(표9[[#This Row],[Team]],표1[],3,0) -> 1000
A14: =VLOOKUP($H14,AWS!$A:$H,2,0) -> AWS | B14: =VLOOKUP($H14,AWS!$A:$H,3,0) -> KRAFTON HQ | C14: =VLOOKUP($H14,AWS!$A:$H,4,0) -> PUBG STUDIO | D14: =VLOOKUP($H14,AWS!$A:$H,5,0) -> Game Security Engineering Dept. | E14: =VLOOKUP($H14,AWS!$A:$H,6,0) -> Dark and Darker_Mobile | F14: =VLOOKUP(표9[[#This Row],[Team]],표1[[내역]:[코스트 센터]],2,0) -> 100415 | G14: =VLOOKUP(표9[[#This Row],[Project]],표2[],2,0) -> P100030073 | H14: aws_ab-anticheat-service@bluehole.net(799954618127) | I14: =VLOOKUP($H14,AWS!$A:$H,8,0) -> 황범석 | J14: =VLOOKUP($H14,AWS!$A:$H,8,0) -> 황범석 | K14: v | L14: 1671608 | M14: 1845569 | N14: 1915815 | O14: 1909640 | P14: 1842532 | Q14: 2014054 | R14: 1980991 | S14: 2014224 | T14: 1331949 | U14: 0 | V14: 0 | W14: =ROUND(표9[[#This Row],[Apr 2026 (USD or KRW)]],0) -> 0 | Y14: =표9[[#This Row],[Apr 2027(KRW)]]-표9[[#This Row],[Mar 2026(KRW)]] -> 0 | Z14: =IF(V14=0,"",(W14-V14)/V14) | AA14: =VLOOKUP(표9[[#This Row],[Team]],표1[],3,0) -> 1000
A15: =VLOOKUP($H15,AWS!$A:$H,2,0) -> AWS | B15: =VLOOKUP($H15,AWS!$A:$H,3,0) -> Neptune | C15: =VLOOKUP($H15,AWS!$A:$H,4,0) -> Neptune | D15: =VLOOKUP($H15,AWS!$A:$H,5,0) -> 0 | E15: =VLOOKUP($H15,AWS!$A:$H,6,0) -> 0 | F15: =VLOOKUP(표9[[#This Row],[Team]],표1[[내역]:[코스트 센터]],2,0) -> #N/A | G15: =VLOOKUP(표9[[#This Row],[Project]],표2[],2,0) -> #N/A | H15: aws_adx_001@adxcorp.kr(302454496823) | I15: =VLOOKUP($H15,AWS!$A:$H,7,0) -> 0 | J15: =VLOOKUP($H15,AWS!$A:$H,8,0) -> 0 | N15: 18362681 | O15: 18359745 | P15: 17889520 | Q15: 19810937 | R15: 22521870 | S15: 23347104 | T15: 21843596 | U15: 17375608 | V15: 21201908 | W15: =ROUND(표9[[#This Row],[Apr 2026 (USD or KRW)]],0) -> 0 | Y15: =표9[[#This Row],[Apr 2027(KRW)]]-표9[[#This Row],[Mar 2026(KRW)]] -> -21201908 | Z15: =IF(V15=0,"",(W15-V15)/V15) -> -1 | AA15: =VLOOKUP(표9[[#This Row],[Team]],표1[],3,0) -> #N/A
A16: =VLOOKUP($H16,AWS!$A:$H,2,0) -> AWS | B16: =VLOOKUP($H16,AWS!$A:$H,3,0) -> Neptune | C16: =VLOOKUP($H16,AWS!$A:$H,4,0) -> Neptune | D16: =VLOOKUP($H16,AWS!$A:$H,5,0) -> 0 | E16: =VLOOKUP($H16,AWS!$A:$H,6,0) -> 0 | F16: =VLOOKUP(표9[[#This Row],[Team]],표1[[내역]:[코스트 센터]],2,0) -> #N/A | G16: =VLOOKUP(표9[[#This Row],[Project]],표2[],2,0) -> #N/A | H16: aws_adx_002@adxcorp.kr(796181577313) | I16: =VLOOKUP($H16,AWS!$A:$H,7,0) -> 0 | J16: =VLOOKUP($H16,AWS!$A:$H,8,0) -> 0 | N16: 15739959 | O16: 11897051 | P16: 14014693 | Q16: 12523100 | R16: 12159154 | S16: 14756395 | T16: 17951593 | U16: 13279139 | V16: 15292648 | W16: =ROUND(표9[[#This Row],[Apr 2026 (USD or KRW)]],0) -> 0 | Y16: =표9[[#This Row],[Apr 2027(KRW)]]-표9[[#This Row],[Mar 2026(KRW)]] -> -15292648 | Z16: =IF(V16=0,"",(W16-V16)/V16) -> -1 | AA16: =VLOOKUP(표9[[#This Row],[Team]],표1[],3,0) -> #N/A
A17: =VLOOKUP($H17,AWS!$A:$H,2,0) -> AWS | B17: =VLOOKUP($H17,AWS!$A:$H,3,0) -> Neptune | C17: =VLOOKUP($H17,AWS!$A:$H,4,0) -> Neptune | D17: =VLOOKUP($H17,AWS!$A:$H,5,0) -> 0 | E17: =VLOOKUP($H17,AWS!$A:$H,6,0) -> 0 | F17: =VLOOKUP(표9[[#This Row],[Team]],표1[[내역]:[코스트 센터]],2,0) -> #N/A | G17: =VLOOKUP(표9[[#This Row],[Project]],표2[],2,0) -> #N/A | H17: aws_adx_003@adxcorp.kr(765348431472) | I17: =VLOOKUP($H17,AWS!$A:$H,7,0) -> 0 | J17: =VLOOKUP($H17,AWS!$A:$H,8,0) -> 0 | N17: 2338429 | O17: 2051754 | P17: 1930885 | Q17: 2298205 | R17: 2156992 | S17: 2218858 | T17: 2139444 | U17: 1934424 | V17: 2179676 | W17: =ROUND(표9[[#This Row],[Apr 2026 (USD or KRW)]],0) -> 0 | Y17: =표9[[#This Row],[Apr 2027(KRW)]]-표9[[#This Row],[Mar 2026(KRW)]] -> -2179676 | Z17: =IF(V17=0,"",(W17-V17)/V17) -> -1 | AA17: =VLOOKUP(표9[[#This Row],[Team]],표1[],3,0) -> #N/A
A18: =VLOOKUP($H18,AWS!$A:$H,2,0) -> AWS | B18: =VLOOKUP($H18,AWS!$A:$H,3,0) -> Neptune | C18: =VLOOKUP($H18,AWS!$A:$H,4,0) -> Neptune | D18: =VLOOKUP($H18,AWS!$A:$H,5,0) -> 0 | E18: =VLOOKUP($H18,AWS!$A:$H,6,0) -> 0 | F18: =VLOOKUP(표9[[#This Row],[Team]],표1[[내역]:[코스트 센터]],2,0) -> #N/A | G18: =VLOOKUP(표9[[#This Row],[Project]],표2[],2,0) -> #N/A | H18: aws_adx_004@adxcorp.kr(142379511204) | J18: =VLOOKUP($H18,AWS!$A:$H,8,0) -> 0 | N18: 266511 | O18: 277368 | P18: 262240 | Q18: 275974 | R18: 274748 | S18: 277807 | T18: 276367 | U18: 249269 | V18: 292732 | W18: =ROUND(표9[[#This Row],[Apr 2026 (USD or KRW)]],0) -> 0 | Y18: =표9[[#This Row],[Apr 2027(KRW)]]-표9[[#This Row],[Mar 2026(KRW)]] -> -292732 | Z18: =IF(V18=0,"",(W18-V18)/V18) -> -1 | AA18: =VLOOKUP(표9[[#This Row],[Team]],표1[],3,0) -> #N/A
A19: =VLOOKUP($H19,AWS!$A:$H,2,0) -> AWS | B19: =VLOOKUP($H19,AWS!$A:$H,3,0) -> Neptune | C19: =VLOOKUP($H19,AWS!$A:$H,4,0) -> Neptune | D19: =VLOOKUP($H19,AWS!$A:$H,5,0) -> 0 | E19: =VLOOKUP($H19,AWS!$A:$H,6,0) -> 0 | F19: =VLOOKUP(표9[[#This Row],[Team]],표1[[내역]:[코스트 센터]],2,0) -> #N/A | G19: =VLOOKUP(표9[[#This Row],[Project]],표2[],2,0) -> #N/A | H19: aws_adx_005@adxcorp.kr(139869765471) | I19: =VLOOKUP($H19,AWS!$A:$H,7,0) -> 0 | J19: =VLOOKUP($H19,AWS!$A:$H,8,0) -> 0 | N19: 3707959 | O19: 3735238 | P19: 3645859 | Q19: 3796250 | R19: 3809735 | S19: 3804670 | T19: 3772958 | U19: 3535747 | V19: 4056545 | W19: =ROUND(표9[[#This Row],[Apr 2026 (USD or KRW)]],0) -> 0 | Y19: =표9[[#This Row],[Apr 2027(KRW)]]-표9[[#This Row],[Mar 2026(KRW)]] -> -4056545 | Z19: =IF(V19=0,"",(W19-V19)/V19) -> -1 | AA19: =VLOOKUP(표9[[#This Row],[Team]],표1[],3,0) -> #N/A
A20: =VLOOKUP($H20,AWS!$A:$H,2,0) -> AWS | B20: =VLOOKUP($H20,AWS!$A:$H,3,0) -> Neptune | C20: =VLOOKUP($H20,AWS!$A:$H,4,0) -> Neptune | D20: =VLOOKUP($H20,AWS!$A:$H,5,0) -> 0 | E20: =VLOOKUP($H20,AWS!$A:$H,6,0) -> 0 | F20: =VLOOKUP(표9[[#This Row],[Team]],표1[[내역]:[코스트 센터]],2,0) -> #N/A | G20: =VLOOKUP(표9[[#This Row],[Project]],표2[],2,0) -> #N/A | H20: aws_adx_007@adxcorp.kr(495653056399) | I20: =VLOOKUP($H20,AWS!$A:$H,7,0) -> 0 | J20: =VLOOKUP($H20,AWS!$A:$H,8,0) -> 0 | N20: 4392 | O20: 10885 | P20: 5102 | Q20: 5212 | R20: 5091 | S20: 4994 | T20: 5153 | U20: 4869 | V20: 5036 | W20: =ROUND(표9[[#This Row],[Apr 2026 (USD or KRW)]],0) -> 0 | Y20: =표9[[#This Row],[Apr 2027(KRW)]]-표9[[#This Row],[Mar 2026(KRW)]] -> -5036 | Z20: =IF(V20=0,"",(W20-V20)/V20) -> -1 | AA20: =VLOOKUP(표9[[#This Row],[Team]],표1[],3,0) -> #N/A
A21: =VLOOKUP($H21,AWS!$A:$H,2,0) -> AWS | B21: =VLOOKUP($H21,AWS!$A:$H,3,0) -> Neptune | C21: =VLOOKUP($H21,AWS!$A:$H,4,0) -> Neptune | D21: =VLOOKUP($H21,AWS!$A:$H,5,0) -> 0 | E21: =VLOOKUP($H21,AWS!$A:$H,6,0) -> 0 | F21: =VLOOKUP(표9[[#This Row],[Team]],표1[[내역]:[코스트 센터]],2,0) -> #N/A | G21: =VLOOKUP(표9[[#This Row],[Project]],표2[],2,0) -> #N/A | H21: aws_adx_008@adxcorp.kr(126271033811) | I21: =VLOOKUP($H21,AWS!$A:$H,7,0) -> 0 | J21: =VLOOKUP($H21,AWS!$A:$H,8,0) -> 0 | O21: 43207 | P21: 1990105 | Q21: 2536230 | R21: 4860583 | S21: 5393691 | T21: 2881278 | U21: 2400417 | V21: 4925923 | W21: =ROUND(표9[[#This Row],[Apr 2026 (USD or KRW)]],0) -> 0 | Y21: =표9[[#This Row],[Apr 2027(KRW)]]-표9[[#This Row],[Mar 2026(KRW)]] -> -4925923 | Z21: =IF(V21=0,"",(W21-V21)/V21) -> -1 | AA21: =VLOOKUP(표9[[#This Row],[Team]],표1[],3,0) -> #N/A
A22: =VLOOKUP($H22,AWS!$A:$H,2,0) -> AWS | B22: =VLOOKUP($H22,AWS!$A:$H,3,0) -> KRAFTON HQ | C22: =VLOOKUP($H22,AWS!$A:$H,4,0) -> KRAFTON HQ | D22: =VLOOKUP($H22,AWS!$A:$H,5,0) -> IT Dept. | E22: =VLOOKUP($H22,AWS!$A:$H,6,0) -> OVERHEAD/OTHERS | F22: =VLOOKUP(표9[[#This Row],[Team]],표1[[내역]:[코스트 센터]],2,0) -> 100036 | G22: =VLOOKUP(표9[[#This Row],[Project]],표2[],2,0) -> I100099999 | H22: aws_bcp_prd@bluehole.net(439802505510) | I22: =VLOOKUP($H22,AWS!$A:$H,8,0) -> 김승훈 | J22: =VLOOKUP($H22,AWS!$A:$H,8,0) -> 김승훈 | L22: 5134845 | M22: 5039340 | N22: 5308753 | O22: 5447553 | P22: 5572764 | Q22: 6727361 | R22: 7513091 | S22: 13408344 | T22: 14033032 | U22: 13099289 | V22: 15925469 | W22: =ROUND(표9[[#This Row],[Apr 2026 (USD or KRW)]],0) -> 0 | Y22: =표9[[#This Row],[Apr 2027(KRW)]]-표9[[#This Row],[Mar 2026(KRW)]] -> -15925469 | Z22: =IF(V22=0,"",(W22-V22)/V22) -> -1 | AA22: =VLOOKUP(표9[[#This Row],[Team]],표1[],3,0) -> 1000
A23: =VLOOKUP($H23,AWS!$A:$H,2,0) -> AWS | B23: =VLOOKUP($H23,AWS!$A:$H,3,0) -> KRAFTON HQ | C23: =VLOOKUP($H23,AWS!$A:$H,4,0) -> KRAFTON HQ | D23: =VLOOKUP($H23,AWS!$A:$H,5,0) -> Global Subsidiary Management Team | E23: =VLOOKUP($H23,AWS!$A:$H,6,0) -> OVERHEAD/OTHERS | F23: =VLOOKUP(표9[[#This Row],[Team]],표1[[내역]:[코스트 센터]],2,0) -> 101712 | G23: =VLOOKUP(표9[[#This Row],[Project]],표2[],2,0) -> I100099999 | H23: AWS_between.dev@krafton.com(616709738515) | I23: =VLOOKUP($H23,AWS!$A:$H,8,0) -> 김재현 | J23: =VLOOKUP($H23,AWS!$A:$H,8,0) -> 김재현 | L23: 799019 | M23: 792837 | N23: 939615 | O23: 1327074 | P23: 1391627 | Q23: 1497582 | R23: 1515281 | S23: 1595865 | T23: 1116148 | U23: 134854 | V23: 139070 | W23: =ROUND(표9[[#This Row],[Apr 2026 (USD or KRW)]],0) -> 0 | Y23: =표9[[#This Row],[Apr 2027(KRW)]]-표9[[#This Row],[Mar 2026(KRW)]] -> -139070 | Z23: =IF(V23=0,"",(W23-V23)/V23) -> -1 | AA23: =VLOOKUP(표9[[#This Row],[Team]],표1[],3,0) -> 1000
A24: =VLOOKUP($H24,AWS!$A:$H,2,0) -> AWS | B24: =VLOOKUP($H24,AWS!$A:$H,3,0) -> KRAFTON HQ | C24: =VLOOKUP($H24,AWS!$A:$H,4,0) -> SDS | D24: =VLOOKUP($H24,AWS!$A:$H,5,0) -> Striking Distance Studios | E24: =VLOOKUP($H24,AWS!$A:$H,6,0) -> The Callisto Protocol | F24: =VLOOKUP(표9[[#This Row],[Team]],표1[[내역]:[코스트 센터]],2,0) -> 100561 | G24: =VLOOKUP(표9[[#This Row],[Project]],표2[],2,0) -> P100010013 | H24: AWS_blackbox-dev@sds.com(659459735321) | I24: =VLOOKUP($H24,AWS!$A:$H,8,0) -> Jordan Yerkes | J24: =VLOOKUP($H24,AWS!$A:$H,8,0) -> Jordan Yerkes | L24: 4067515 | M24: 5393574 | S24: 0 | T24: 0 | U24: 0 | V24: 0 | W24: =ROUND(표9[[#This Row],[Apr 2026 (USD or KRW)]],0) -> 0 | Y24: =표9[[#This Row],[Apr 2027(KRW)]]-표9[[#This Row],[Mar 2026(KRW)]] -> 0 | Z24: =IF(V24=0,"",(W24-V24)/V24) | AA24: =VLOOKUP(표9[[#This Row],[Team]],표1[],3,0) -> 1000
A25: =VLOOKUP($H25,AWS!$A:$H,2,0) -> AWS | B25: =VLOOKUP($H25,AWS!$A:$H,3,0) -> KRAFTON HQ | C25: =VLOOKUP($H25,AWS!$A:$H,4,0) -> InZOI Studio | D25: =VLOOKUP($H25,AWS!$A:$H,5,0) -> inZOI Server Team | E25: =VLOOKUP($H25,AWS!$A:$H,6,0) -> inZOI | F25: =VLOOKUP(표9[[#This Row],[Team]],표1[[내역]:[코스트 센터]],2,0) -> #N/A | G25: =VLOOKUP(표9[[#This Row],[Project]],표2[],2,0) -> P100010055 | H25: aws_blue@bluehole.net(611812385851) | I25: =VLOOKUP($H25,AWS!$A:$H,8,0) -> 조재욱 | J25: =VLOOKUP($H25,AWS!$A:$H,8,0) -> 조재욱 | L25: 831954 | M25: 819863 | N25: 1055148 | O25: 1457941 | P25: 1458274 | Q25: 1496773 | R25: 1510606 | S25: 1884390 | T25: 2078934 | U25: 1849540 | V25: 2470019 | W25: =ROUND(표9[[#This Row],[Apr 2026 (USD or KRW)]],0) -> 0 | Y25: =표9[[#This Row],[Apr 2027(KRW)]]-표9[[#This Row],[Mar 2026(KRW)]] -> -2470019 | Z25: =IF(V25=0,"",(W25-V25)/V25) -> -1 | AA25: =VLOOKUP(표9[[#This Row],[Team]],표1[],3,0) -> #N/A
A26: =VLOOKUP($H26,AWS!$A:$H,2,0) -> AWS | B26: =VLOOKUP($H26,AWS!$A:$H,3,0) -> KRAFTON HQ | C26: =VLOOKUP($H26,AWS!$A:$H,4,0) -> KRAFTON HQ | D26: =VLOOKUP($H26,AWS!$A:$H,5,0) -> Data Engineering Dept. | E26: =VLOOKUP($H26,AWS!$A:$H,6,0) -> OVERHEAD/OTHERS | F26: =VLOOKUP(표9[[#This Row],[Team]],표1[[내역]:[코스트 센터]],2,0) -> 100212 | G26: =VLOOKUP(표9[[#This Row],[Project]],표2[],2,0) -> I100099999 | H26: AWS_data-tech@krafton.com(272510915182) | I26: =VLOOKUP($H26,AWS!$A:$H,8,0) -> 김시훈 | J26: =VLOOKUP($H26,AWS!$A:$H,8,0) -> 김시훈 | K26: v | L26: 307937120 | M26: 346814364 | N26: 2998736452 | O26: 408151249 | P26: 437260317 | Q26: 545351157 | R26: 547726239 | S26: 3310004714 | T26: 567365183 | U26: 1032195117 | V26: 1173899035 | W26: =ROUND(표9[[#This Row],[Apr 2026 (USD or KRW)]],0) -> 0 | Y26: =표9[[#This Row],[Apr 2027(KRW)]]-표9[[#This Row],[Mar 2026(KRW)]] -> -1173899035 | Z26: =IF(V26=0,"",(W26-V26)/V26) -> -1 | AA26: =VLOOKUP(표9[[#This Row],[Team]],표1[],3,0) -> 1000
A27: =VLOOKUP($H27,AWS!$A:$H,2,0) -> AWS | B27: =VLOOKUP($H27,AWS!$A:$H,3,0) -> Research | C27: =VLOOKUP($H27,AWS!$A:$H,4,0) -> Research | D27: =VLOOKUP($H27,AWS!$A:$H,5,0) -> AI research center | E27: =VLOOKUP($H27,AWS!$A:$H,6,0) -> OVERHEAD/OTHERS | F27: =VLOOKUP(표9[[#This Row],[Team]],표1[[내역]:[코스트 센터]],2,0) -> 100677 | G27: =VLOOKUP(표9[[#This Row],[Project]],표2[],2,0) -> I100099999 | H27: aws_de_mturk@krafton.com(036022206166) | I27: =VLOOKUP($H27,AWS!$A:$H,8,0) -> 김범수 | J27: =VLOOKUP($H27,AWS!$A:$H,8,0) -> 김범수 | L27: 6535 | M27: 14339 | N27: 5980 | O27: 11207 | P27: 8576 | Q27: 9012 | R27: 9819 | S27: 1937257 | T27: 1917819 | U27: 3078092 | V27: 3596090 | W27: =ROUND(표9[[#This Row],[Apr 2026 (USD or KRW)]],0) -> 0 | Y27: =표9[[#This Row],[Apr 2027(KRW)]]-표9[[#This Row],[Mar 2026(KRW)]] -> -3596090 | Z27: =IF(V27=0,"",(W27-V27)/V27) -> -1 | AA27: =VLOOKUP(표9[[#This Row],[Team]],표1[],3,0) -> 1000
A28: =VLOOKUP($H28,AWS!$A:$H,2,0) -> AWS | B28: =VLOOKUP($H28,AWS!$A:$H,3,0) -> Risingwings | C28: =VLOOKUP($H28,AWS!$A:$H,4,0) -> Risingwings | D28: =VLOOKUP($H28,AWS!$A:$H,5,0) -> RW Tech Support Dept. | E28: =VLOOKUP($H28,AWS!$A:$H,6,0) -> 0 | F28: =VLOOKUP(표9[[#This Row],[Team]],표1[[내역]:[코스트 센터]],2,0) -> #N/A | G28: =VLOOKUP(표9[[#This Row],[Project]],표2[],2,0) -> #N/A | H28: AWS_defensederby@risingwings.com(183323689126) | I28: =VLOOKUP($H28,AWS!$A:$H,7,0) -> 허지웅 | J28: =VLOOKUP($H28,AWS!$A:$H,8,0) -> 허지웅 | L28: 105729 | M28: 113452 | N28: 105347 | O28: 126266 | P28: 5287 | S28: 0 | T28: 0 | U28: 0 | V28: 0 | W28: =ROUND(표9[[#This Row],[Apr 2026 (USD or KRW)]],0) -> 0 | Y28: =표9[[#This Row],[Apr 2027(KRW)]]-표9[[#This Row],[Mar 2026(KRW)]] -> 0 | Z28: =IF(V28=0,"",(W28-V28)/V28) | AA28: =VLOOKUP(표9[[#This Row],[Team]],표1[],3,0) -> #N/A
A29: =VLOOKUP($H29,AWS!$A:$H,2,0) -> AWS | B29: =VLOOKUP($H29,AWS!$A:$H,3,0) -> Research | C29: =VLOOKUP($H29,AWS!$A:$H,4,0) -> Research | D29: =VLOOKUP($H29,AWS!$A:$H,5,0) -> ML Sys & Ops Team | E29: =VLOOKUP($H29,AWS!$A:$H,6,0) -> DEEP LEARNING | F29: =VLOOKUP(표9[[#This Row],[Team]],표1[[내역]:[코스트 센터]],2,0) -> 100810 | G29: =VLOOKUP(표9[[#This Row],[Project]],표2[],2,0) -> I100090817 | H29: AWS_DLD_dev@bluehole.net(171503962539) | I29: =VLOOKUP($H29,AWS!$A:$H,8,0) -> 김지윤 | J29: =VLOOKUP($H29,AWS!$A:$H,8,0) -> 김지윤 | K29: v | L29: 4468067 | M29: 3980672 | N29: 4538114 | O29: 5204950 | P29: 5155923 | Q29: 5363119 | R29: 5440702 | S29: 5415029 | T29: 5187691 | U29: 3957122 | V29: 4330547 | W29: =ROUND(표9[[#This Row],[Apr 2026 (USD or KRW)]],0) -> 0 | Y29: =표9[[#This Row],[Apr 2027(KRW)]]-표9[[#This Row],[Mar 2026(KRW)]] -> -4330547 | Z29: =IF(V29=0,"",(W29-V29)/V29) -> -1 | AA29: =VLOOKUP(표9[[#This Row],[Team]],표1[],3,0) -> 1000
A30: =VLOOKUP($H30,AWS!$A:$H,2,0) -> AWS | B30: =VLOOKUP($H30,AWS!$A:$H,3,0) -> Dreamotion | C30: =VLOOKUP($H30,AWS!$A:$H,4,0) -> Dreamotion | D30: =VLOOKUP($H30,AWS!$A:$H,5,0) -> Project MLP Team | E30: =VLOOKUP($H30,AWS!$A:$H,6,0) -> Road to Valor: Empire | F30: =VLOOKUP(표9[[#This Row],[Team]],표1[[내역]:[코스트 센터]],2,0) -> #N/A | G30: =VLOOKUP(표9[[#This Row],[Project]],표2[],2,0) -> #N/A | H30: AWS_Dreamotion-Empire@krafton.com(828925677153) | I30: =VLOOKUP($H30,AWS!$A:$H,7,0) -> 류성중 | J30: =VLOOKUP($H30,AWS!$A:$H,8,0) -> 류성중 | L30: 991576 | M30: 954507 | N30: 1187771 | O30: 989785 | P30: 971495 | Q30: 1265010 | R30: 1261521 | S30: 1246848 | T30: 1135164 | U30: 988449 | V30: 1151781 | W30: =ROUND(표9[[#This Row],[Apr 2026 (USD or KRW)]],0) -> 0 | Y30: =표9[[#This Row],[Apr 2027(KRW)]]-표9[[#This Row],[Mar 2026(KRW)]] -> -1151781 | Z30: =IF(V30=0,"",(W30-V30)/V30) -> -1 | AA30: =VLOOKUP(표9[[#This Row],[Team]],표1[],3,0) -> #N/A
A31: =VLOOKUP($H31,AWS!$A:$H,2,0) -> AWS | B31: =VLOOKUP($H31,AWS!$A:$H,3,0) -> Dreamotion | C31: =VLOOKUP($H31,AWS!$A:$H,4,0) -> Dreamotion | D31: =VLOOKUP($H31,AWS!$A:$H,5,0) -> Project MLP Team | E31: =VLOOKUP($H31,AWS!$A:$H,6,0) -> GunStrider: Tap Strike | F31: =VLOOKUP(표9[[#This Row],[Team]],표1[[내역]:[코스트 센터]],2,0) -> #N/A | G31: =VLOOKUP(표9[[#This Row],[Project]],표2[],2,0) -> #N/A | H31: AWS_Dreamotion-GunStrider@krafton.com(286067354613) | I31: =VLOOKUP($H31,AWS!$A:$H,7,0) -> 류성중 | J31: =VLOOKUP($H31,AWS!$A:$H,8,0) -> 류성중 | L31: 83727 | M31: 87910 | N31: 81718 | O31: 88431 | P31: 89268 | Q31: 89355 | R31: 96054 | S31: 87995 | T31: 84221 | U31: 76625 | V31: 107386 | W31: =ROUND(표9[[#This Row],[Apr 2026 (USD or KRW)]],0) -> 0 | Y31: =표9[[#This Row],[Apr 2027(KRW)]]-표9[[#This Row],[Mar 2026(KRW)]] -> -107386 | Z31: =IF(V31=0,"",(W31-V31)/V31) -> -1 | AA31: =VLOOKUP(표9[[#This Row],[Team]],표1[],3,0) -> #N/A
A32: =VLOOKUP($H32,AWS!$A:$H,2,0) -> AWS | B32: =VLOOKUP($H32,AWS!$A:$H,3,0) -> Dreamotion | C32: =VLOOKUP($H32,AWS!$A:$H,4,0) -> Dreamotion | D32: =VLOOKUP($H32,AWS!$A:$H,5,0) -> Project MLP Team | E32: =VLOOKUP($H32,AWS!$A:$H,6,0) -> Road to valor : world war2 | F32: =VLOOKUP(표9[[#This Row],[Team]],표1[[내역]:[코스트 센터]],2,0) -> #N/A | G32: =VLOOKUP(표9[[#This Row],[Project]],표2[],2,0) -> #N/A | H32: AWS_Dreamotion-RoadToValor@krafton.com(531219453947) | I32: =VLOOKUP($H32,AWS!$A:$H,7,0) -> 류성중 | J32: =VLOOKUP($H32,AWS!$A:$H,8,0) -> 류성중 | L32: 1568594 | M32: 1449646 | N32: 1606994 | O32: 1539701 | P32: 1404477 | Q32: 1613721 | R32: 1610654 | S32: 1589427 | T32: 1488166 | U32: 1366984 | V32: 1478086 | W32: =ROUND(표9[[#This Row],[Apr 2026 (USD or KRW)]],0) -> 0 | Y32: =표9[[#This Row],[Apr 2027(KRW)]]-표9[[#This Row],[Mar 2026(KRW)]] -> -1478086 | Z32: =IF(V32=0,"",(W32-V32)/V32) -> -1 | AA32: =VLOOKUP(표9[[#This Row],[Team]],표1[],3,0) -> #N/A
A33: =VLOOKUP($H33,AWS!$A:$H,2,0) -> AWS | B33: =VLOOKUP($H33,AWS!$A:$H,3,0) -> Dreamotion | C33: =VLOOKUP($H33,AWS!$A:$H,4,0) -> Dreamotion | D33: =VLOOKUP($H33,AWS!$A:$H,5,0) -> Project MLP Team | E33: =VLOOKUP($H33,AWS!$A:$H,6,0) -> Ronin: The Last Samurai | F33: =VLOOKUP(표9[[#This Row],[Team]],표1[[내역]:[코스트 센터]],2,0) -> #N/A | G33: =VLOOKUP(표9[[#This Row],[Project]],표2[],2,0) -> #N/A | H33: AWS_Dreamotion-Ronin@krafton.com(071872665424) | I33: =VLOOKUP($H33,AWS!$A:$H,7,0) -> 류성중 | J33: =VLOOKUP($H33,AWS!$A:$H,8,0) -> 류성중 | L33: 1115503 | M33: 1075700 | N33: 1302948 | O33: 1104698 | P33: 1085000 | Q33: 1376322 | R33: 1376876 | S33: 1367556 | T33: 1248339 | U33: 1104470 | V33: 1266915 | W33: =ROUND(표9[[#This Row],[Apr 2026 (USD or KRW)]],0) -> 0 | Y33: =표9[[#This Row],[Apr 2027(KRW)]]-표9[[#This Row],[Mar 2026(KRW)]] -> -1266915 | Z33: =IF(V33=0,"",(W33-V33)/V33) -> -1 | AA33: =VLOOKUP(표9[[#This Row],[Team]],표1[],3,0) -> #N/A
A34: =VLOOKUP($H34,AWS!$A:$H,2,0) -> AWS | B34: =VLOOKUP($H34,AWS!$A:$H,3,0) -> KRAFTON HQ | C34: =VLOOKUP($H34,AWS!$A:$H,4,0) -> KRAFTON HQ | D34: =VLOOKUP($H34,AWS!$A:$H,5,0) -> Security Dept. | E34: =VLOOKUP($H34,AWS!$A:$H,6,0) -> OVERHEAD/OTHERS | F34: =VLOOKUP(표9[[#This Row],[Team]],표1[[내역]:[코스트 센터]],2,0) -> 101451 | G34: =VLOOKUP(표9[[#This Row],[Project]],표2[],2,0) -> I100099999 | H34: aws_engineering_security@bluehole.net(635942867251) | I34: =VLOOKUP($H34,AWS!$A:$H,8,0) -> 홍준화 | J34: =VLOOKUP($H34,AWS!$A:$H,8,0) -> 홍준화 | K34: v | L34: 2555506 | M34: 2534955 | N34: 2522685 | O34: 2604888 | P34: 3294806 | Q34: 3017838 | R34: 2282260 | S34: 2303702 | T34: 2848630 | U34: 3687339 | V34: 6340867 | W34: =ROUND(표9[[#This Row],[Apr 2026 (USD or KRW)]],0) -> 0 | Y34: =표9[[#This Row],[Apr 2027(KRW)]]-표9[[#This Row],[Mar 2026(KRW)]] -> -6340867 | Z34: =IF(V34=0,"",(W34-V34)/V34) -> -1 | AA34: =VLOOKUP(표9[[#This Row],[Team]],표1[],3,0) -> 1000
A35: =VLOOKUP($H35,AWS!$A:$H,2,0) -> AWS | B35: =VLOOKUP($H35,AWS!$A:$H,3,0) -> KRAFTON HQ | C35: =VLOOKUP($H35,AWS!$A:$H,4,0) -> KRAFTON HQ | D35: =VLOOKUP($H35,AWS!$A:$H,5,0) -> DevData Engineering Team | E35: =VLOOKUP($H35,AWS!$A:$H,6,0) -> BATTLEGROUNDS_PC/CONSOLE | F35: =VLOOKUP(표9[[#This Row],[Team]],표1[[내역]:[코스트 센터]],2,0) -> 101721 | G35: =VLOOKUP(표9[[#This Row],[Project]],표2[],2,0) -> P100010012 | H35: aws_esports_streaming@bluehole.net(559478286890) | I35: =VLOOKUP($H35,AWS!$A:$H,8,0) -> 안연주 | J35: =VLOOKUP($H35,AWS!$A:$H,8,0) -> 안연주 | L35: 2817722 | M35: 2727336 | N35: 2845993 | O35: 2883454 | P35: 3008796 | Q35: 2956316 | R35: 2739119 | S35: 3008046 | T35: 3093269 | U35: 2983882 | V35: 3672617 | W35: =ROUND(표9[[#This Row],[Apr 2026 (USD or KRW)]],0) -> 0 | Y35: =표9[[#This Row],[Apr 2027(KRW)]]-표9[[#This Row],[Mar 2026(KRW)]] -> -3672617 | Z35: =IF(V35=0,"",(W35-V35)/V35) -> -1 | AA35: =VLOOKUP(표9[[#This Row],[Team]],표1[],3,0) -> 1000
A36: =VLOOKUP($H36,AWS!$A:$H,2,0) -> AWS | B36: =VLOOKUP($H36,AWS!$A:$H,3,0) -> BLUEHOLE | C36: =VLOOKUP($H36,AWS!$A:$H,4,0) -> BLUEHOLE | D36: =VLOOKUP($H36,AWS!$A:$H,5,0) -> [N/A] AB Unit | E36: =VLOOKUP($H36,AWS!$A:$H,6,0) -> Dark and Darker_Mobile | F36: =VLOOKUP(표9[[#This Row],[Team]],표1[[내역]:[코스트 센터]],2,0) -> 110099 | G36: =VLOOKUP(표9[[#This Row],[Project]],표2[],2,0) -> P100030073 | H36: AWS_FF@bluehole.net(257405109560) | I36: =VLOOKUP($H36,AWS!$A:$H,8,0) -> 이민재 | J36: =VLOOKUP($H36,AWS!$A:$H,8,0) -> 이민재 | L36: 42095789 | M36: 45747688 | N36: 42442625 | O36: 38897801 | P36: 34960534 | Q36: 37665835 | R36: 34825214 | S36: 37528129 | T36: 33286868 | U36: 6640088 | V36: 7603373 | W36: =ROUND(표9[[#This Row],[Apr 2026 (USD or KRW)]],0) -> 0 | Y36: =표9[[#This Row],[Apr 2027(KRW)]]-표9[[#This Row],[Mar 2026(KRW)]] -> -7603373 | Z36: =IF(V36=0,"",(W36-V36)/V36) -> -1 | AA36: =VLOOKUP(표9[[#This Row],[Team]],표1[],3,0) -> 1100
A37: =VLOOKUP($H37,AWS!$A:$H,2,0) -> AWS | B37: =VLOOKUP($H37,AWS!$A:$H,3,0) -> KRAFTON HQ | C37: =VLOOKUP($H37,AWS!$A:$H,4,0) -> KRAFTON HQ | D37: =VLOOKUP($H37,AWS!$A:$H,5,0) -> Data Engineering Dept. | E37: =VLOOKUP($H37,AWS!$A:$H,6,0) -> OVERHEAD/OTHERS | F37: =VLOOKUP(표9[[#This Row],[Team]],표1[[내역]:[코스트 센터]],2,0) -> 100212 | G37: =VLOOKUP(표9[[#This Row],[Project]],표2[],2,0) -> I100099999 | H37: aws_gamesight@bluehole.net(171101943282) | I37: =VLOOKUP($H37,AWS!$A:$H,8,0) -> 김시훈 | J37: =VLOOKUP($H37,AWS!$A:$H,8,0) -> 김시훈 | K37: v | L37: 8195128 | M37: 8153395 | N37: 8860559 | O37: 8606579 | P37: 6658898 | Q37: 6363951 | R37: 6407382 | S37: 6319086 | T37: 6012372 | U37: 5550141 | V37: 6396490 | W37: =ROUND(표9[[#This Row],[Apr 2026 (USD or KRW)]],0) -> 0 | Y37: =표9[[#This Row],[Apr 2027(KRW)]]-표9[[#This Row],[Mar 2026(KRW)]] -> -6396490 | Z37: =IF(V37=0,"",(W37-V37)/V37) -> -1 | AA37: =VLOOKUP(표9[[#This Row],[Team]],표1[],3,0) -> 1000
A38: =VLOOKUP($H38,AWS!$A:$H,2,0) -> AWS | B38: =VLOOKUP($H38,AWS!$A:$H,3,0) -> KRAFTON HQ | C38: =VLOOKUP($H38,AWS!$A:$H,4,0) -> PUBG STUDIO | D38: =VLOOKUP($H38,AWS!$A:$H,5,0) -> [N/A] IN Publishing Production Team_HQ | E38: =VLOOKUP($H38,AWS!$A:$H,6,0) -> BULLET ECHO | F38: =VLOOKUP(표9[[#This Row],[Team]],표1[[내역]:[코스트 센터]],2,0) -> 101716 | G38: =VLOOKUP(표9[[#This Row],[Project]],표2[],2,0) -> P100030851 | H38: aws_india_publishing@bluehole.net(397907563279) | I38: =VLOOKUP($H38,AWS!$A:$H,8,0) -> 박지현 | J38: =VLOOKUP($H38,AWS!$A:$H,8,0) -> 박지현 | L38: 6193 | M38: 14057 | N38: 5893 | O38: 11055 | P38: 8537 | Q38: 9001 | R38: 9888 | S38: 8685 | T38: 10668 | U38: 9183 | V38: 3764 | W38: =ROUND(표9[[#This Row],[Apr 2026 (USD or KRW)]],0) -> 0 | Y38: =표9[[#This Row],[Apr 2027(KRW)]]-표9[[#This Row],[Mar 2026(KRW)]] -> -3764 | Z38: =IF(V38=0,"",(W38-V38)/V38) -> -1 | AA38: =VLOOKUP(표9[[#This Row],[Team]],표1[],3,0) -> 1000
A39: =VLOOKUP($H39,AWS!$A:$H,2,0) -> AWS | B39: =VLOOKUP($H39,AWS!$A:$H,3,0) -> KRAFTON HQ | C39: =VLOOKUP($H39,AWS!$A:$H,4,0) -> KRAFTON HQ | D39: =VLOOKUP($H39,AWS!$A:$H,5,0) -> IT Platform Engineering Team | E39: =VLOOKUP($H39,AWS!$A:$H,6,0) -> OVERHEAD/OTHERS | F39: =VLOOKUP(표9[[#This Row],[Team]],표1[[내역]:[코스트 센터]],2,0) -> 100024 | G39: =VLOOKUP(표9[[#This Row],[Project]],표2[],2,0) -> I100099999 | H39: aws_it-dev-ot-01@krafton.com(585980862501) | I39: =VLOOKUP($H39,AWS!$A:$H,8,0) -> 김주한 | J39: =VLOOKUP($H39,AWS!$A:$H,8,0) -> 김주한 | K39: v | S39: 252601 | T39: 432633 | U39: 90580 | V39: 3452 | W39: =ROUND(표9[[#This Row],[Apr 2026 (USD or KRW)]],0) -> 0 | Y39: =표9[[#This Row],[Apr 2027(KRW)]]-표9[[#This Row],[Mar 2026(KRW)]] -> -3452 | Z39: =IF(V39=0,"",(W39-V39)/V39) -> -1 | AA39: =VLOOKUP(표9[[#This Row],[Team]],표1[],3,0) -> 1000
A40: =VLOOKUP($H40,AWS!$A:$H,2,0) -> AWS | B40: =VLOOKUP($H40,AWS!$A:$H,3,0) -> KRAFTON HQ | C40: =VLOOKUP($H40,AWS!$A:$H,4,0) -> KRAFTON HQ | D40: =VLOOKUP($H40,AWS!$A:$H,5,0) -> IT Platform Engineering Team | E40: =VLOOKUP($H40,AWS!$A:$H,6,0) -> OVERHEAD/OTHERS | F40: =VLOOKUP(표9[[#This Row],[Team]],표1[[내역]:[코스트 센터]],2,0) -> 100024 | G40: =VLOOKUP(표9[[#This Row],[Project]],표2[],2,0) -> I100099999 | H40: aws_it-dev-ot-02@krafton.com(997525377919) | I40: =VLOOKUP($H40,AWS!$A:$H,8,0) -> 김주한 | J40: =VLOOKUP($H40,AWS!$A:$H,8,0) -> 김주한 | K40: v | S40: 167431 | T40: 465435 | U40: 274896 | V40: 51198 | W40: =ROUND(표9[[#This Row],[Apr 2026 (USD or KRW)]],0) -> 0 | Y40: =표9[[#This Row],[Apr 2027(KRW)]]-표9[[#This Row],[Mar 2026(KRW)]] -> -51198 | Z40: =IF(V40=0,"",(W40-V40)/V40) -> -1 | AA40: =VLOOKUP(표9[[#This Row],[Team]],표1[],3,0) -> 1000
...

Sheet Pivot by CW
A1: Please don't change this sheet and data. If necessary, contact Yunseul Lee via Slack 1:1 DM.
A2: Pivot (Cost per Cloud Provider)
A3: 행 레이블 | B3: 합계 : Mar 2026(KRW)
A4: Akamai | B4: 504766397
A5: KRAFTON HQ | B5: 504766397
A6: AWS | B6: 5793090939
A7: BLUEHOLE | B7: 17336978
A8: KRAFTON HQ | B8: 3837743597
A9: Research | B9: 79749506
A10: DLD | B10: 1858260858
A11: Azure | B11: 4420285606
A12: BLUEHOLE | B12: 24498736
A13: KRAFTON HQ | B13: 4241412983
A14: Research | B14: 154373887
A15: Datadog | B15: 347293612
... A22: 총합계 | B22: 1.2238995e+10
A31: Entity | B31: (다중 항목)
A33: 행 레이블 | B33: 합계 : July 2025(KRW) | C33: 합계 : Aug 2025(KRW) | D33: 합계 : Sep 2025(KRW) | E33: 합계 : Oct 2025(KRW) | F33: 합계 : Nov 2025(KRW) | G33: 합계 : Dec 2025(KRW) | H33: 합계 : Jan 2026(KRW) | I33: 합계 : Feb 2026(KRW) | J33: 합계 : Mar 2026(KRW) | K33: SUM | L33: =SUM(L34:L37) -> 3841286474 | M33: =SUM(L66,L69,L90,L99,L106,L116,L118,L122) -> #REF!
A34: BLUEHOLE | B34: 76512173 | C34: 71845839 | D34: 68077618 | E34: 72894895 | F34: 68822600 | G34: 73450500 | H34: 68330496 | I34: 39758714 | J34: 0 | K34: KRAFTON | L34: =SUM(J35:J43,J45:J54,J56:J59) -> 0 | M34: =SUM(L66,L69,L90,L99,L106,L116,L118) -> 2.4429155e+10
A35: Flyway Games | H35: 149904 | I35: 0 | J35: 0 | K35: RESEARCH | L35: =GETPIVOTDATA("합계 : Feb 2026(KRW)",$A$33,"Studio","Research") -> 222950439 | M35: =M122 -> 63576.28
A36: KRAFTON America | B36: 4680739 | C36: 4769599 | D36: 4503085 | E36: 4681703 | F36: 3056075 | G36: 4894166 | H36: 4845201 | I36: 146371 | J36: 0 | K36: DLD | L36: =GETPIVOTDATA("합계 : Feb 2026(KRW)",$A$33,"Studio","DLD") -> 3578577321
A37: KRAFTON HQ | B37: 8929736489 | C37: 5873437065 | D37: 5886019140 | E37: 5.9878105e+09 | F37: 6733154391 | G37: 9017495476 | H37: 5818565835 | I37: 5883691161 | J37: 0 | K37: BLUEHOLE | L37: =GETPIVOTDATA("합계 : Feb 2026(KRW)",$A$33,"Studio","BLUEHOLE") -> 39758714
A38: Mad Glory | B38: 10378012 | C38: 16438773 | D38: 20227398 | E38: 21665822 | F38: 19223375 | G38: 23491836 | H38: 23596073 | I38: 21690710 | J38: 0
A39: OVERDARE | B39: 31558871 | C39: 32141643 | D39: 40572449 | E39: 46471422 | F39: 33916708 | G39: 54902746 | H39: 59291320 | I39: 2493 | J39: 0
A40: Montreal Studio | B40: 3354486 | C40: 3340268 | D40: 3307884 | E40: 3427707 | F40: 3507599 | G40: 3449608 | H40: 3603187 | I40: 3771584 | J40: 0
A41: PUBG NewState | B41: 151058066 | C41: 147805535 | D41: 136755797 | E41: 1.4868654e+08 | F41: 149106806 | G41: 147568021 | H41: 133703152 | I41: 114052539 | J41: 0
A42: PUBG STUDIO | B42: 2725470596 | C42: 2646114816 | D42: 2646577566 | E42: 2.8537828e+09 | F42: 2.8757888e+09 | G42: 3115138625 | H42: 3023196236 | I42: 2562048571 | J42: 0
A43: ReLu Games | C43: 42 | D43: 23 | E43: 406.202 | F43: 8243 | G43: 11205 | H43: 4009 | I43: 0 | J43: 0
A44: Research | B44: 237452954 | C44: 182822172 | D44: 199077426 | E44: 1.8560827e+08 | F44: 195563752 | G44: 203029290 | H44: 221748189 | I44: 222950439 | J44: 0
A45: SDS | B45: 59390196 | C45: 50621161 | D45: 47395192 | E45: 51245023 | F45: 48741047 | G45: 43067663 | H45: 42252384 | I45: 29119948 | J45: 0
A46: KRAFTON CHINA | B46: 0 | C46: 0 | D46: 0 | E46: 0 | F46: 0 | G46: 0 | H46: 0 | I46: 0 | J46: 0
A47: KRAFTON EUROPE B.V. | B47: 6 | C47: 6 | D47: 54 | E47: 1370.9384 | F47: 738 | G47: 247 | H47: 211 | I47: 246 | J47: 0
A48: InZOI Studio | B48: 1378863 | C48: 1790717 | D48: 1770163 | E48: 1832858.6 | F48: 1731820 | G48: 2238136 | H48: 2290139 | I48: 1858983 | J48: 0
A49: 5Minlab | C49: 4644 | D49: 6003 | E49: 9917.1099 | F49: 53909 | G49: 186029 | H49: 268711 | I49: 129914 | J49: 0
A50: Tango Gameworks | B50: 852610 | C50: 859209 | D50: 819580 | E50: 875797 | F50: 865537 | G50: 913051 | H50: 863269 | I50: 766731 | J50: 0
A51: Nautilus | H51: 13362 | I51: 1435706 | J51: 0
A52: Vector North | B52: 5506954 | C52: 5176171 | D52: 4171477 | E52: 4336485.6 | F52: 3641829 | G52: 0 | H52: 0 | I52: 0 | J52: 0
A53: Omnicraftlabs | C53: 808 | D53: 14506 | E53: 16318 | F53: 12535 | G53: 13166 | H53: 13112 | I53: 11112 | J53: 0
A54: OCL GW Server Team | C54: 808 | D54: 14506 | E54: 16318 | F54: 12535 | G54: 13166 | H54: 13112 | I54: 11112 | J54: 0
A55: GW | C55: 808 | D55: 14506 | E55: 16318 | F55: 12535 | G55: 13166 | H55: 13112 | I55: 11112 | J55: 0
...

Sheet Pivot
A3: 행 레이블 | B3: 합계 : Mar 2026(KRW)
A4: Akamai | B4: 504766397
A5: KRAFTON HQ | B5: 504766397
A6: AWS | B6: 5793090939
A7: BLUEHOLE | B7: 17336978
A8: DLD | B8: 1858260858
A9: KRAFTON HQ | B9: 3837743597
A10: Research | B10: 79749506
A11: Azure | B11: 4420285606
A12: BLUEHOLE | B12: 24498736
A13: KRAFTON HQ | B13: 4241412983
A14: Research | B14: 154373887
A15: Datadog | B15: 343643598
... A26: 총합계 | B26: 12910469675
A29: 행 레이블 | B29: 합계 : Apr 2025(KRW) | C29: 합계 : May 2025(KRW) | D29: 합계 : June 2025(KRW) | E29: 합계 : July 2025(KRW) | F29: 합계 : Aug 2025(KRW) | G29: 합계 : Sep 2025(KRW) | H29: 합계 : Oct 2025(KRW) | I29: 합계 : Nov 2025(KRW) | J29: 합계 : Dec 2025(KRW) | K29: 합계 : Jan 2026(KRW) | L29: 합계 : Feb 2026(KRW) | M29: 합계 : Mar 2026(KRW)
A30: BLUEHOLE | B30: 51038109 | C30: 76376626 | D30: 79132451 | E30: 76512173 | F30: 71845839 | G30: 68077618 | H30: 72894895 | I30: 68822600 | J30: 73450500 | K30: 68330496 | L30: 39758714 | M30: 42434768
A31: BLUEHOLE | B31: 51038109 | C31: 76376626 | D31: 79132451 | E31: 76512173 | F31: 71845839 | G31: 68077618 | H31: 72894895 | I31: 68822600 | J31: 73450500 | K31: 68330496 | L31: 39758714 | M31: 42434768
A32: DLD | F32: 14007 | G32: 7274281183 | H32: 708782514 | I32: 873132036 | J32: 981513185 | K32: 1246271540 | L32: 3578577321 | M32: 1858260858
A33: DLD | F33: 14007 | G33: 7274281183 | H33: 708782514 | I33: 873132036 | J33: 981513185 | K33: 1246271540 | L33: 3578577321 | M33: 1858260858
A34: KRAFTON HQ | B34: 4859521709 | C34: 8374385121 | D34: 8101955028 | E34: 11923365888 | F34: 8782500457 | G34: 8792140317 | H34: 9.1248566e+09 | I34: 9.8730128e+09 | J34: 12413823883 | K34: 9113546558 | L34: 8622960212 | M34: 10775650656
A35: 5Minlab | F35: 4644 | G35: 6003 | H35: 9917.1099 | I35: 53909 | J35: 186029 | K35: 268711 | L35: 129914 | M35: 823883
A36: Flyway Games | K36: 149904 | L36: 0 | M36: 0
A37: InZOI Studio | B37: 847662 | C37: 831954 | D37: 1030238 | E37: 1378863 | F37: 1790717 | G37: 1770163 | H37: 1832858.6 | I37: 1731820 | J37: 2238136 | K37: 2290139 | L37: 1858983 | M37: 2505427
A38: JofSoft | J38: 13387 | K38: 4422 | L38: 6985 | M38: 8083
A39: KRAFTON America | B39: 4617164 | C39: 3751157 | D39: 4614580 | E39: 4680739 | F39: 4769599 | G39: 4503085 | H39: 4681703 | I39: 3056075 | J39: 4894166 | K39: 4845201 | L39: 146371 | M39: 3490397
A40: KRAFTON CHINA | B40: 0 | C40: 0 | D40: 7987883 | E40: 0 | F40: 0 | G40: 0 | H40: 0 | I40: 0 | J40: 0 | K40: 0 | L40: 0 | M40: 0
A41: KRAFTON EUROPE B.V. | B41: 0 | C41: 5 | D41: 5 | E41: 6 | F41: 6 | G41: 54 | H41: 1370.9384 | I41: 738 | J41: 247 | K41: 211 | L41: 246 | M41: 232
A42: KRAFTON HQ | B42: 2835777766 | C42: 5518968068 | D42: 5248795558 | E42: 8929736489 | F42: 5873437065 | G42: 5886019140 | H42: 5.9878105e+09 | I42: 6733154391 | J42: 9017495476 | K42: 5818565835 | L42: 5883667990 | M42: 7351033957
A43: KRAFTON India | G43: 0 | H43: 12032 | I43: 184044 | J43: 223311 | K43: 246622 | L43: 1620872 | M43: 4849806
A44: KRAFTON Montreal | J44: 7065 | K44: 18151 | L44: 20331 | M44: 22161
A45: Ludo | L45: 23171 | M45: 36913
A46: Mad Glory | B46: 7595237 | C46: 7654818 | D46: 6913775 | E46: 10378012 | F46: 16438773 | G46: 20227398 | H46: 21665822 | I46: 19223375 | J46: 23491836 | K46: 23596073 | L46: 21690710 | M46: 27133587
A47: Montreal Studio | B47: 7943453 | C47: 3335034 | D47: 3265803 | E47: 3354486 | F47: 3340268 | G47: 3307884 | H47: 3427707 | I47: 3507599 | J47: 3449608 | K47: 3603187 | L47: 3771584 | M47: 4056006
A48: Nautilus | K48: 13362 | L48: 1435706 | M48: 4175979
A49: NineB | K49: 370274 | L49: 1789499 | M49: 1360790
A50: OliveTree Games | I50: 19309 | J50: 210145 | K50: 250984 | L50: 796456 | M50: 1161356
A51: Omnicraftlabs | F51: 808 | G51: 14506 | H51: 16318 | I51: 12535 | J51: 13166 | K51: 13112 | L51: 11112 | M51: 13060
A52: OVERDARE | B52: 29785612 | C52: 18023639 | D52: 24304360 | E52: 31558871 | F52: 32141643 | G52: 40572449 | H52: 46471422 | I52: 33916708 | J52: 54902746 | K52: 59291320 | L52: 2493 | M52: 40179134
A53: PUBG NewState | B53: 166388350 | C53: 157941611 | D53: 146060949 | E53: 151058066 | F53: 147805535 | G53: 136755797 | H53: 1.4868654e+08 | I53: 149106806 | J53: 147568021 | K53: 133703152 | L53: 114052539 | M53: 129061819
A54: PUBG STUDIO | B54: 1718618659 | C54: 2577899498 | D54: 2577406939 | E54: 2725470596 | F54: 2646114816 | G54: 2646577566 | H54: 2.8537828e+09 | I54: 2.8757888e+09 | J54: 3115138625 | K54: 3023196236 | L54: 2562048571 | M54: 3180483030
...

Sheet ToDo
A1: provider | B1: entity | C1: ID | D1: cost USD | E1: cost KRW (exc VAT) | F1: 과금내역수신여부 | G1: 검수마감 | H1: 세금계산서요청 | I1: 세금계산서수신여부 | J1: 송장헤더 | K1: 송장 항목 | L1: 송장승인제출 | M1: 자회사청구(concur 3.불공제) - 25일경
A2: Akamai | B2: KRAFTON HQ | E2: 429920311 | M2: n/a
A3: AWS | B3: KRAFTON HQ | E3: 2999851500 | F3: V | G3: V | H3: V | I3: V | J3: V | K3: V | L3: V | M3: KRAFTON Americas(146,182원), PUBG Mad Glory(20,797,881원), Montreal Studio(3,771,584원), inZOI(9,443원), SDS(26,440,842원), Tango Gameworks(766,731원), Nautilus(1,435,706원), OmniCraftlabs(11,112원), KRAFTON India(1,620,872원), JofSoft(6,985원), NineB(1,789,499원), OliveTree Games(796,456원) | O3: 7654818
A4: AWS | B4: Research | E4: 69007423 | F4: V | G4: V | H4: V | I4: V | J4: V | K4: V | L4: V | M4: 연구소 비용으로 계산서 분리 | O4: 3335034
A5: AWS | B5: DLD | E5: 3578577321 | M5: 국책과제 비용으로 계산서 분리
A6: AWS | B6: GPU SP 잔금 | M6: 국책과제 비용으로 계산서 분리
A7: AWS | B7: BLUEHOLE | E7: 14687809 | F7: V | G7: V | H7: V | I7: V | J7: V | K7: V | L7: V | M7: n/a | O7: 79400785
A8: Azure | B8: KRAFTON HQ | E8: 4036518236 | F8: V | H8: V | M8: Montreal Studio(20,331원), Krafton Europe B.V.(246원)
A9: Azure | B9: Research | E9: 153943016 | F9: V | H9: V | M9: 연구소 비용으로 계산서 분리
A10: Azure | B10: BLUEHOLE | E10: 24438009 | F10: V | H10: V | M10: n/a
A11: Datadog | B11: KRAFTON HQ | E11: 279810255 | M11: PUBG Mad Glory(892,829원), SDS(2,679,106원)
A12: Datadog | B12: BLUEHOLE | E12: 632896 | M12: n/a
A13: GCP | B13: KRAFTON HQ | E13: 262708856 | F13: V | G13: V | H13: V | I13: V | J13: V | K13: V | L13: V | M13: KRAFTON Americas(189원), OVERDARE KOREA, Inc.(2,493원), 5Minlab(129,914원) | O13: 4614580
A14: GWS | B14: KRAFTON HQ | C14: GWS | E14: =921417+10657674 -> 11579091 | F14: V | G14: V | H14: V | I14: V | J14: V | K14: V | L14: V | M14: KRAFTON JAPAN, Inc.(994,716원), Krafton Americas, Inc(568,409원), PUBG India(532,884원), Krafton Europe B.V.(319,730원), KRAFTON MONTREAL STUDIO, INC.(106,577원), PUBG Madglory(106,577원), Bluehole Studio, Inc.(71,051원), OVERDARE KOREA, Inc.(71,051원), NAUTILUS MOBILE APP PRIVATE LIMITED(35,526원) | N14: =310.5*N16 -> 423366.75
A15: GWS | B15: KRAFTON HQ | C15: Gemini&AI Ultra | E15: 46183254 | F15: V | G15: V | H15: V | I15: V | J15: V | K15: V | L15: V | M15: inZOI Studio, Inc.(2,167,060원), Krafton Americas, Inc.(710,512원), KRAFTON CHINA(177,628원), KRAFTON EUROPE B.V.(497,358원), KRAFTON INDIA(603,935원), KRAFTON MONTREAL STUDIO, INC.(35,526원), OmniCraft Labs, Inc.(994,716원), PUBG Mad Glory, LLC(213,153원), RisingWings, Inc.(1,136,819원), Striking Distance Studios Spain, S.L.(71,051원)
A16: Tencent | B16: KRAFTON HQ | E16: 469289205 | F16: V | H16: V | I16: V | L16: V | N16: 1363.5
A17: Tencent | B17: BLUEHOLE
A18: Yandex | B18: KRAFTON HQ | D18: 63576.28 | E18: 87099504 | F18: V | H18: V | I18: V | L18: V
E19: =SUM(E2:E18) -> 12464246686
D20: yandex 제외(USD) | E20: =SUM(E2:E17) -> 12377147182 | M20: =145778+21074628+3427707+49638086+875797+4336445+12032 -> 79510473
D21: Gemini 제외(SW) | M21: =1505713+16318 -> 1522031
M22: =E3-M20-M21 -> 2918818996
C32: 담당자 | D32: 제품 | E32: 제조사 | F32: Entity | G32: 진행상황 | H32: 금액
C33: 이윤슬 | D33: Akamai | E33: Akamai | F33: 크래프톤 | H33: =SUM(E2:E2) -> 429920311
D34: 메가존클라우드 | E34: Datadog | F34: 크래프톤 | H34: =E11 -> 279810255
F35: Bluehole | H35: =E12 -> 632896
D36: SK | E36: 크래프톤 | F36: 크래프톤 | H36: =E8 -> 4036518236
E37: Research | F37: 크래프톤(Research) | H37: =E9 -> 153943016
E38: Bluehole | F38: Bluehole | H38: =E10 -> 24438009
D39: SK | E39: Tencent | F39: 크래프톤 | H39: =E16 -> 469289205
D40: Iron Hive doo Beograd | E40: Yandex | F40: 크래프톤 | H40: =E18 -> 87099504
D41: GS 네오텍 | E41: AWS | F41: 크래프톤 | H41: =SUM(E3,E5:E5) -> 6578428821
F42: 크래프톤(Research) | H42: =E4 -> 69007423
F43: Bluehole | H43: =E7 -> 14687809
D44: LG CNS | E44: GCP | F44: 크래프톤 | H44: =E13 -> 262708856
E45: GWS | F45: 크래프톤 | H45: =E14 -> 11579091
E46: Gemini | F46: 크래프톤 | H46: =E15 -> 46183254
F47: KRW | H47: =SUM(H33:H46)-H40 -> 12377147182
F48: USD | H48: =D18 -> 63576.28

Sheet Akamai
A1: Please don't change this sheet and data. If necessary, contact Chaewon Jung via Slack 1:1 DM.
A2: Account ID | B2: Provider | C2: Entity | D2: Studio | E2: Team | F2: Project | G2: Owner | H2: Cost verifier | I2: comment | J2: contact verifed?
A3: Dark&DarkerMoblie | B3: Akamai | C3: KRAFTON HQ | D3: KRAFTON HQ | E3: Publishing Tech PM Part | F3: Dark and Darker_Mobile | G3: 김정언 | H3: 김정언 | J3: v
A4: NitroSmash | B4: Akamai | C4: KRAFTON HQ | D4: KRAFTON HQ | E4: Publishing Tech PM Part | F4: OVERHEAD/OTHERS | G4: 김정언 | H4: 김정언
A5: XTRM | B5: Akamai | C5: KRAFTON HQ | D5: PUBG NewState | E5: [N/A]New State Dev Div. | F5: PUBG:NEW STATE | G5: 최진욱 | H5: 김태완 | J5: v
A6: NewStateMobile | B6: Akamai | C6: KRAFTON HQ | D6: PUBG NewState | E6: [N/A]New State Dev Div. | F6: PUBG:NEW STATE | G6: 최진욱 | H6: 김태완
A7: IT Dept | B7: Akamai | C7: KRAFTON HQ | D7: KRAFTON HQ | E7: IT Dept. | F7: OVERHEAD/OTHERS | G7: 백용원 | H7: 백용원
A8: PUBGM Mobile (BGMI) | B8: Akamai | C8: KRAFTON HQ | D8: KRAFTON HQ | E8: BGMI DevOps Team | F8: BATTLEGROUNDS_MOBILE | G8: 이돈현 | H8: 이돈현 | J8: v
A9: @PUBG Mobile | B9: Akamai | C9: KRAFTON HQ | D9: KRAFTON HQ | E9: BGMI DevOps Team | F9: BATTLEGROUNDS_MOBILE_IN | G9: 이돈현 | H9: 이돈현 | J9: v
A10: PUBG India | B10: Akamai | C10: KRAFTON HQ | D10: KRAFTON HQ | E10: BGMI DevOps Team | F10: (2022)BATTLEGROUNDS_MOBILE_IN | G10: 이돈현 | H10: 이돈현
A11: SSL Network Access-Third-party - VIP | B11: Akamai | C11: KRAFTON HQ | D11: KRAFTON HQ | E11: IT Dept. | F11: OVERHEAD/OTHERS | G11: 이윤슬 | H11: 이윤슬 | J11: v
A12: Global Traffic Management | B12: Akamai | C12: KRAFTON HQ | D12: KRAFTON HQ | E12: IT Dept. | F12: OVERHEAD/OTHERS | G12: 이윤슬 | H12: 이윤슬
A13: Protect&Perform SOA with Premium | B13: Akamai | C13: KRAFTON HQ | D13: KRAFTON HQ | E13: IT Dept. | F13: OVERHEAD/OTHERS | G13: 이윤슬 | H13: 이윤슬
A14: GPP Dept | B14: Akamai | C14: KRAFTON HQ | D14: KRAFTON HQ | E14: KOS Engineering Dept. | F14: GPP | G14: 이의석 | H14: 이의석 | J14: v
A15: Migaloo | B15: Akamai | C15: OVERDARE | D15: OVERDARE | E15: OVDR Platform Engineering Team | F15: OVERHEAD/OTHERS | G15: 이제우 | H15: 이제우 | J15: v
A16: PUBG LItePC-Download | B16: Akamai | C16: KRAFTON HQ | D16: PUBG STUDIO | E16: PUBG PC&Console Dev Div. | F16: BATTLEGROUNDS_PC/CONSOLE | G16: 김정헌 | H16: 최준석 | J16: v
A17: PUBG Prod-Live Lobby | B17: Akamai | C17: KRAFTON HQ | D17: PUBG STUDIO | E17: PUBG PC&Console Dev Div. | F17: BATTLEGROUNDS_PC/CONSOLE | G17: 김정헌 | H17: 최준석 | J17: v
A18: PUBG PC/Console | B18: Akamai | C18: KRAFTON HQ | D18: KRAFTON HQ | E18: PUBG PC&Console Dev Div. | F18: BATTLEGROUNDS_PC/CONSOLE | G18: 김정헌 | H18: 최준석
A19: intra platform | B19: Akamai | C19: KRAFTON HQ | D19: KRAFTON HQ | E19: IT Dept. | F19: OVERHEAD/OTHERS | G19: 홍성철 | H19: 홍성철 | J19: v
A20: App & API Protector with Advanced Security Management Plus DSA | B20: Akamai | C20: KRAFTON HQ | D20: KRAFTON HQ | E20: IT Dept. | F20: OVERHEAD/OTHERS | G20: 정채원 | H20: Deleted | J20: v
A21: Bot Manager Premier | B21: Akamai | C21: KRAFTON HQ | D21: KRAFTON HQ | E21: IT Dept. | F21: OVERHEAD/OTHERS | G21: 정채원 | H21: Deleted | J21: v
A22: Cloud Wrapper | B22: Akamai | C22: KRAFTON HQ | D22: KRAFTON HQ | E22: IT Dept. | F22: OVERHEAD/OTHERS | G22: 정채원 | H22: Deleted | J22: v
A23: Global Traffic Management - Standard | B23: Akamai | C23: KRAFTON HQ | D23: KRAFTON HQ | E23: IT Dept. | F23: OVERHEAD/OTHERS | G23: 정채원 | H23: Deleted | J23: v
A24: Protect & Perform SOA with Premium | B24: Akamai | C24: KRAFTON HQ | D24: KRAFTON HQ | E24: IT Dept. | F24: OVERHEAD/OTHERS | G24: 정채원 | H24: Deleted | J24: v
A25: RG rerun (etc) | B25: Akamai | C25: KRAFTON HQ | D25: PUBG STUDIO | E25: PUBG Dev Div. | F25: BATTLEGROUNDS_PC/CONSOLE | G25: 정채원 | H25: Deleted | J25: v
A26: ch-BGMI | B26: Akamai | C26: KRAFTON HQ | D26: KRAFTON HQ | E26: BGMI DevOps Team | F26: BATTLEGROUNDS_MOBILE_IN | G26: 이돈현 | H26: Deleted | J26: v
A27: ch-NEWSTATE | B27: Akamai | C27: KRAFTON HQ | D27: PUBG NewState | E27: [N/A]New State Dev Div. | F27: PUBG:NEW STATE | G27: 최진욱 | H27: Deleted | J27: v
A28: ch-NEWSTATE2 | B28: Akamai | C28: KRAFTON HQ | D28: PUBG NewState | E28: [N/A]New State Dev Div. | F28: PUBG:NEW STATE | G28: 최진욱 | H28: Deleted | J28: v
A29: ch-PUBG | B29: Akamai | C29: KRAFTON HQ | D29: PUBG STUDIO | E29: PUBG PC&Console Dev Div. | F29: BATTLEGROUNDS_PC/CONSOLE | G29: 김정헌 | H29: Deleted | J29: v
A30: ch-OTHERS | B30: Akamai | C30: KRAFTON HQ | D30: KRAFTON HQ | E30: IT Dept. | F30: OVERHEAD/OTHERS | G30: 정채원 | H30: Deleted | J30: v
A31: CH-DD | B31: Akamai | C31: KRAFTON HQ | D31: KRAFTON HQ | E31: Publishing Tech PM Part | F31: Dark and Darker_Mobile | G31: 김정언 | H31: Deleted | J31: v

Sheet AWS
A1: Please don't change this sheet and data. If necessary, contact Chanewon Jung via Slack 1:1 DM.
A2: Account | B2: Provider | C2: Entity | D2: Studio | E2: Team | F2: Project | G2: Owner | H2: Cost verifier | I2: comment | J2: Team code | K2: Project code
A3: aws_ab-anticheat-service@bluehole.net(799954618127) | B3: AWS | C3: KRAFTON HQ | D3: PUBG STUDIO | E3: Game Security Engineering Dept. | F3: Dark and Darker_Mobile | G3: 황범석 | H3: 황범석 | I3: AB 안티치트 서비스용 사용예정 (24년 1분기부터) | J3: =VLOOKUP(표4[[#This Row],[Team]],표1[[내역]:[코스트 센터]],2,0) -> 100415 | K3: =VLOOKUP(표4[[#This Row],[Project]],표2[],2,0) -> P100030073
A4: aws_bcp_prd@bluehole.net(439802505510) | B4: AWS | C4: KRAFTON HQ | D4: KRAFTON HQ | E4: IT Dept. | F4: OVERHEAD/OTHERS | G4: 김승훈 | H4: 김승훈 | J4: =VLOOKUP(표4[[#This Row],[Team]],표1[[내역]:[코스트 센터]],2,0) -> 100036 | K4: =VLOOKUP(표4[[#This Row],[Project]],표2[],2,0) -> I100099999
A5: AWS_blackbox-dev@sds.com(659459735321) | B5: AWS | C5: KRAFTON HQ | D5: SDS | E5: Striking Distance Studios | F5: The Callisto Protocol | G5: Minkz Ngo | H5: Jordan Yerkes | J5: =VLOOKUP(표4[[#This Row],[Team]],표1[[내역]:[코스트 센터]],2,0) -> 100561 | K5: =VLOOKUP(표4[[#This Row],[Project]],표2[],2,0) -> P100010013
A6: aws_blue@bluehole.net(611812385851) | B6: AWS | C6: KRAFTON HQ | D6: InZOI Studio | E6: inZOI Server Team | F6: inZOI | G6: 조재욱 | H6: 조재욱 | I6: 24' 11월 Account Owner 를 이상문님에서 조재욱님으로 변경합니다 25' 1월 GS Credit 적용 시작 예정 | J6: =VLOOKUP(표4[[#This Row],[Team]],표1[[내역]:[코스트 센터]],2,0) -> #N/A | K6: =VLOOKUP(표4[[#This Row],[Project]],표2[],2,0) -> P100010055
A7: aws_cloudtrail_dev@bluehole.net(642623655767) | B7: AWS | C7: KRAFTON HQ | D7: KRAFTON HQ | E7: IT Dept. | F7: OVERHEAD/OTHERS | G7: 염화음 | H7: 유영빈 | I7: 1월 중 삭제 예정 | J7: =VLOOKUP(표4[[#This Row],[Team]],표1[[내역]:[코스트 센터]],2,0) -> 100036 | K7: =VLOOKUP(표4[[#This Row],[Project]],표2[],2,0) -> I100099999
A8: AWS_data-tech@krafton.com(272510915182) | B8: AWS | C8: KRAFTON HQ | D8: KRAFTON HQ | E8: Data Engineering Dept. | F8: OVERHEAD/OTHERS | G8: 염화음 | H8: 김시훈 | I8: https://ask.krafton.com/browse/ASKIT-27917, ASKIT-24823 유영빈님이 담당자 변경요청 | J8: =VLOOKUP(표4[[#This Row],[Team]],표1[[내역]:[코스트 센터]],2,0) -> 100212 | K8: =VLOOKUP(표4[[#This Row],[Project]],표2[],2,0) -> I100099999
A9: aws_de_mturk@krafton.com(036022206166) | B9: AWS | C9: Research | D9: Research | E9: AI research center | F9: OVERHEAD/OTHERS | G9: 김범수 | H9: 김범수 | I9: https://ask.krafton.com/browse/ASKIT-38494 | J9: =VLOOKUP(표4[[#This Row],[Team]],표1[[내역]:[코스트 센터]],2,0) -> 100677 | K9: =VLOOKUP(표4[[#This Row],[Project]],표2[],2,0) -> I100099999
A10: AWS_DLD_dev@bluehole.net(171503962539) | B10: AWS | C10: Research | D10: Research | E10: ML Sys & Ops Team | F10: DEEP LEARNING | G10: 이동기 | H10: 김지윤 | I10: https://ask.krafton.com/browse/ASKIT-29089/https://ask.krafton.com/browse/ASKIT-29089, https://jira.krafton.com/browse/ASKIT-24249 | J10: =VLOOKUP(표4[[#This Row],[Team]],표1[[내역]:[코스트 센터]],2,0) -> 100810 | K10: =VLOOKUP(표4[[#This Row],[Project]],표2[],2,0) -> I100090817
A11: AWS_DLD_Prod@bluehole.net(696280989469) | B11: AWS | C11: Research | D11: Research | E11: Data Engineering Dept. | F11: DEEP LEARNING | G11: 유상규 | H11: 유상규 | I11: 24년1~2월에 비용 많이 증가한다고 함 6/5 close/ 삭제 | J11: =VLOOKUP(표4[[#This Row],[Team]],표1[[내역]:[코스트 센터]],2,0) -> 100212 | K11: =VLOOKUP(표4[[#This Row],[Project]],표2[],2,0) -> I100090817
A12: aws_engineering_security@bluehole.net(635942867251) | B12: AWS | C12: KRAFTON HQ | D12: KRAFTON HQ | E12: Security Dept. | F12: OVERHEAD/OTHERS | G12: 홍준화 | H12: 홍준화 | J12: =VLOOKUP(표4[[#This Row],[Team]],표1[[내역]:[코스트 센터]],2,0) -> 101451 | K12: =VLOOKUP(표4[[#This Row],[Project]],표2[],2,0) -> I100099999
A13: aws_esports_streaming@bluehole.net(559478286890) | B13: AWS | C13: KRAFTON HQ | D13: KRAFTON HQ | E13: DevData Engineering Team | F13: BATTLEGROUNDS_PC/CONSOLE | G13: 안연주 | H13: 안연주 | I13: PUBG e-sports Console 대회용 서비스 | J13: =VLOOKUP(표4[[#This Row],[Team]],표1[[내역]:[코스트 센터]],2,0) -> 101721 | K13: =VLOOKUP(표4[[#This Row],[Project]],표2[],2,0) -> P100010012
A14: AWS_FF@bluehole.net(257405109560) | B14: AWS | C14: BLUEHOLE | D14: BLUEHOLE | E14: [N/A] AB Unit | F14: Dark and Darker_Mobile | G14: 이민재 | H14: 이민재 | I14: 담당자 변경 : 김현철 -> 이민재https://ask.krafton.com/browse/ASKIT-34027 FF는 블루홀(개발)/LIVE는 크래프톤(퍼블리싱)-BGMI팀 | J14: =VLOOKUP(표4[[#This Row],[Team]],표1[[내역]:[코스트 센터]],2,0) -> 110099 | K14: =VLOOKUP(표4[[#This Row],[Project]],표2[],2,0) -> P100030073
A15: aws_gamesight@bluehole.net(171101943282) | B15: AWS | C15: KRAFTON HQ | D15: KRAFTON HQ | E15: Data Engineering Dept. | F15: OVERHEAD/OTHERS | G15: 염화음 | H15: 김시훈 | J15: =VLOOKUP(표4[[#This Row],[Team]],표1[[내역]:[코스트 센터]],2,0) -> 100212 | K15: =VLOOKUP(표4[[#This Row],[Project]],표2[],2,0) -> I100099999
A16: aws_krafton_id@bluehole.net(853221784203) | B16: AWS | C16: KRAFTON HQ | D16: KRAFTON HQ | E16: KOS Engineering Dept. | F16: GPP | G16: 신근우 | H16: 신근우 | I16: aws_krafton_id@bluehole.net(853221784203) -> aws_krafton_id@bluehole.net(853221784203)으로 변경 | J16: =VLOOKUP(표4[[#This Row],[Team]],표1[[내역]:[코스트 센터]],2,0) -> 100025 | K16: =VLOOKUP(표4[[#This Row],[Project]],표2[],2,0) -> I100090813
A17: AWS_India-Esports@pubg.com(132802523425) | B17: AWS | C17: KRAFTON HQ | D17: KRAFTON HQ | E17: Service Devops Team | F17: BATTLEGROUNDS_MOBILE | G17: 양장수 | H17: 양장수 | I17: 24' 5/7 account close 완료 | J17: =VLOOKUP(표4[[#This Row],[Team]],표1[[내역]:[코스트 센터]],2,0) -> 100033 | K17: =VLOOKUP(표4[[#This Row],[Project]],표2[],2,0) -> P100030012
A18: AWS_india_publishing@bluehole.net(397907563279) | B18: AWS | C18: KRAFTON HQ | D18: PUBG STUDIO | E18: [N/A] IN Publishing Production Team_HQ | F18: BULLET ECHO | G18: 박지현 | H18: 박지현 | I18: Amplitude 라이선스 구매용/김종환님이신청은했으나 윤슬님 확인 가능-> 박지연님 | J18: =VLOOKUP(표4[[#This Row],[Team]],표1[[내역]:[코스트 센터]],2,0) -> 101716 | K18: =VLOOKUP(표4[[#This Row],[Project]],표2[],2,0) -> P100030851
A19: aws_krafton_ded@bluehole.net(333537382729) | B19: AWS | C19: KRAFTON HQ | D19: KRAFTON HQ | E19: Data Engineering Dept. | F19: OVERHEAD/OTHERS | G19: 염화음 | H19: 김시훈 | J19: =VLOOKUP(표4[[#This Row],[Team]],표1[[내역]:[코스트 센터]],2,0) -> 100212 | K19: =VLOOKUP(표4[[#This Row],[Project]],표2[],2,0) -> I100099999
A20: aws-krafton-ddm-live@krafton.com(975050331843) | B20: AWS | C20: KRAFTON HQ | D20: KRAFTON HQ | E20: Publishing Tech PM Part | F20: Dark and Darker_Mobile | G20: 김정언 | H20: 김정언 | I20: Bluehole AB(DDM) Live 서비스용 AWS 계정/aws-krafton-ddm-live@krafton.com(975050331843)->aws-krafton-ddm-stg@bluehole.net(975050331843)으로 변경 | J20: =VLOOKUP(표4[[#This Row],[Team]],표1[[내역]:[코스트 센터]],2,0) -> 101269 | K20: =VLOOKUP(표4[[#This Row],[Project]],표2[],2,0) -> P100030073
A21: aws_krafton-service-dev-project@bluehole.net(921970894603) | B21: AWS | C21: Research | D21: Research | E21: AI Product Dev Chapter Dept. | F21: DEEP LEARNING | G21: 권승진 | H21: 박준규 | J21: =VLOOKUP(표4[[#This Row],[Team]],표1[[내역]:[코스트 센터]],2,0) -> 102159 | K21: =VLOOKUP(표4[[#This Row],[Project]],표2[],2,0) -> I100090817
A22: aws_kraftonde-sensitive@krafton.com(226547056751) | B22: AWS | C22: KRAFTON HQ | D22: KRAFTON HQ | E22: Data Engineering Dept. | F22: OVERHEAD/OTHERS | G22: 염화음 | H22: 김시훈 | I22: https://ask.krafton.com/browse/ASKIT-27917, ASKIT-24823 유영빈님이 담당자 변경요청, https://ask.krafton.com/browse/ASKIT-38495 | J22: =VLOOKUP(표4[[#This Row],[Team]],표1[[내역]:[코스트 센터]],2,0) -> 100212 | K22: =VLOOKUP(표4[[#This Row],[Project]],표2[],2,0) -> I100099999
A23: AWS_log@krafton.com(873854150592) | B23: AWS | C23: KRAFTON HQ | D23: KRAFTON HQ | E23: KRAFTON HQ | F23: OVERHEAD/OTHERS | G23: 정채원 | H23: Deleted(25.5) | I23: 25.5.16 삭제완료SDS에서 삭제요청했음. 9/30 - 승훈님 확인 | J23: =VLOOKUP(표4[[#This Row],[Team]],표1[[내역]:[코스트 센터]],2,0) -> 100009 | K23: =VLOOKUP(표4[[#This Row],[Project]],표2[],2,0) -> I100099999
A24: aws_migaloo-data@bluehole.net(231111506266) | B24: AWS | C24: OVERDARE | D24: OVERDARE | E24: OVDR GTM Team | F24: OVERHEAD/OTHERS | G24: Deleted | H24: Deleted | I24: 삭제요청 받았음. 그래서 삭제 예정 | J24: =VLOOKUP(표4[[#This Row],[Team]],표1[[내역]:[코스트 센터]],2,0) -> #N/A | K24: =VLOOKUP(표4[[#This Row],[Project]],표2[],2,0) -> I100099999
